Workbook

Sheet Grafici
B1: DATI "TARGA" | F1: ENERGIA CONTENUTA | K1: ENERGIA & EMISSIONI ANNO TIPO | T1: COSTI
B2: Serbatoio | C2: Autonomia | D2: Consumo | F2: Well | G2: Tank | H2: Wheel | I2: η_WtW | K2: Carburante | L2: Energia Utile | M2: Energia primaria richiesta | N2: Emissioni CO2 - 12.000 km | P2: Emissioni totale carburante | Q2: Emissioni costruzione | R2: Emissioni totali | T2: OPEx fuel | V2: OPEx Maintenance | X2: CAPEx | Z2: Costo totale
B3: [l/kWh/kg] | C3: [km] | D3: [kWh/km] | F3: [kWh] | G3: [kWh] | H3: [kWh] | I3: [ - ] | K3: [l/kWh/kg] | L3: [kWh] | M3: [kWh] | N3: WtT - [kgCO2/anno] | O3: TtW [kgCO2/anno] | P3: WtW - [kgCO2/anno] | Q3: [kg/CO2] | R3: [t CO2] | T3: [€/km] | U3: [€/anno] | V3: [€/km] | W3: [€/anno] | X3: [€/anno] | Y3: [€] | Z3: [€/anno] | AA3: [€]
A4: Benzina | B4: 55.75 | C4: 828.03986 | D4: 0.58860563 | F4: 574.06103 | G4: 487.95187 | H4: 121.98797 | I4: 0.2125 | K4: 1008.75 | L4: 8829.0844 | M4: 10387.158 | N4: 582.55313 | O4: 2330.2125 | P4: 2912.7656 | Q4: 6000 | R4: 64.255313 | T4: 0.127775 | U4: 1916.625 | V4: 0.08 | W4: 1200 | X4: 2050 | Y4: 41000 | Z4: 5166.625 | AA4: 103332.5
A5: Diesel | B5: 61 | C5: 1125 | D5: 0.5347674 | F5: 694.35529 | G5: 604.0891 | H5: 193.30851 | I5: 0.2784 | K5: 810 | L5: 8021.511 | M5: 9220.1276 | N5: 320.76 | O5: 2138.4 | P5: 2459.16 | Q5: 6000 | R5: 55.1832 | T5: 0.0972 | U5: 1458 | V5: 0.065 | W5: 975 | X5: 2250 | Y5: 45000 | Z5: 4683 | AA5: 93660
A6: Elettrico rete | B6: 59.5 | C6: 435.69079 | D6: 0.13666667 | F6: 119 | G6: 59.5 | H6: 53.55 | I6: 0.45 | K6: 2050 | L6: 2050 | M6: 4100 | N6: 440.75 | O6: 0 | P6: 440.75 | Q6: 12000 | R6: 20.815 | T6: 0.042366667 | U6: 635.5 | V6: 0.03 | W6: 450 | X6: 1916.6667 | Y6: 38333.333 | Z6: 3002.1667 | AA6: 60043.333
A7: Elettrico autoprodotto | B7: 59.5 | C7: 435.69079 | D7: 0.13666667 | F7: 66.111111 | G7: 59.5 | H7: 53.55 | I7: 0.81 | K7: 2050 | L7: 2050 | M7: 2277.7778 | N7: 112.75 | O7: 0 | P7: 112.75 | Q7: 12000 | R7: 14.255 | T7: 0.0328 | U7: 492 | V7: 0.03 | W7: 450 | X7: 1916.6667 | Y7: 38333.333 | Z7: 2858.6667 | AA7: 57173.333
A8: Idrogeno Grigio | B8: 5.965 | C8: 702.36711 | D8: 0.3333 | F8: 284.01921 | G8: 198.81345 | H8: 89.466053 | I8: 0.315 | K8: 150 | L8: 4999.5 | M8: 7142.1429 | N8: 1650 | O8: 0 | P8: 1650 | Q8: 14000 | R8: 47 | T8: 0.02 | U8: 300 | V8: 0.055 | W8: 825 | X8: 3375 | Y8: 67500 | Z8: 4500 | AA8: 90000
A9: Idrogeno rete | B9: 5.965 | C9: 702.36711 | D9: 0.3333 | F9: 722.958 | G9: 198.81345 | H9: 89.466053 | I9: 0.12375 | K9: 150 | L9: 4999.5 | M9: 18180 | N9: 1935 | O9: 0 | P9: 1935 | Q9: 14000 | R9: 52.7 | T9: 0.2 | U9: 3000 | V9: 0.055 | W9: 825 | X9: 3375 | Y9: 67500 | Z9: 7200 | AA9: 144000
A10: Idrogeno autoprodotto | B10: 5.965 | C10: 702.36711 | D10: 0.3333 | F10: 320.66685 | G10: 198.81345 | H10: 89.466053 | I10: 0.279 | K10: 150 | L10: 4999.5 | M10: 8063.7097 | N10: 450 | O10: 0 | P10: 450 | Q10: 14000 | R10: 23 | T10: 0.15 | U10: 2250 | V10: 0.055 | W10: 825 | X10: 3375 | Y10: 67500 | Z10: 6450 | AA10: 129000
B13: 1 excel per categoria | E13: PARAMETRI | I13: CALORE
E14: Autonomia
E15: "Costo" energetico | I15: "Costo" energetico approvvigionamento fuel [kWh]
E16: Emissioni (in pila) | I16: Emissioni (in pila)
E17: Costi (in pila) | I17: Costi (in pila)
E19: Interfaccia Grafica | H19: Produrre un excel protetto con dashboard (con parametri modificabili) +assunzioni+grafici identificati
E20: Scenari per categoria

Sheet AUTO
C2: DATI "TARGA" | G2: ENERGIA CONTENUTA | L2: ENERGIA & EMISSIONI ANNO TIPO | U2: COSTI
C3: Serbatoio | D3: Autonomia | E3: Consumo | G3: Well | H3: Tank | I3: Wheel | J3: η_WtW | L3: Carburante | M3: Energia Utile | N3: Energia primaria richiesta | O3: Emissioni CO2 | Q3: Emissioni totale carburante | R3: Emissioni costruzione | S3: Emissioni totali | U3: OPEx fuel | W3: OPEx Maintenance | Y3: CAPEx | AA3: Costo totale
C4: [l/kWh/kg] | D4: [km] | E4: [kWh/km] | G4: [kWh] | H4: [kWh] | I4: [kWh] | J4: [ - ] | L4: [l/kWh/kg] | M4: [kWh] | N4: [kWh] | O4: WtT - [kgCO2/anno] | P4: TtW [kgCO2/anno] | Q4: WtW - [kgCO2/anno] | R4: [kg/CO2] | S4: [t CO2] | U4: [€/km] | V4: [€/anno] | W4: [€/km] | X4: [€/anno] | Y4: [€/anno] | Z4: [€] | AA4: [€/anno] | AB4: [€]
B5: Benzina | C5: =C38 -> 55.75 | D5: =D38 -> 828.03986 | E5: =F38 -> 0.58860563 | G5: =H5/M32 -> 574.06103 | H5: =C5*Dati!G3 -> 487.95187 | I5: =H5*N32 -> 121.98797 | J5: =I5/G5 -> 0.2125 | L5: =C17*E38 -> 1008.75 | M5: =$C$17*E5 -> 8829.0844 | N5: =M5/M32 -> 10387.158 | O5: =$C$17*E5*M41 -> 582.55313 | P5: =$C$17*E5*M50 -> 2330.2125 | Q5: =P5+O5 -> 2912.7656 | R5: =M59 -> 6000 | S5: =(R5+(P5+O5)*$C$16)/1000 -> 64.255313 | U5: =F20*E5 -> 0.127775 | V5: =$C$17*U5 -> 1916.625 | W5: =Dati!D69 -> 0.08 | X5: =W5*$C$17 -> 1200 | Y5: =Z5/$C$16 -> 2050 | Z5: =G38 -> 41000 | AA5: =AB5/$C$16 -> 5166.625 | AB5: =(X5+V5)*$C$16+Z5 -> 103332.5
B6: Diesel | C6: 61 | D6: =D65 -> 1125 | E6: =F65 -> 0.5347674 | G6: =H6/M33 -> 694.35529 | H6: =C6*Dati!G4 -> 604.0891 | I6: =H6*N33 -> 193.30851 | J6: =I6/G6 -> 0.2784 | L6: =C17*E65/100 -> 810 | M6: =$C$17*E6 -> 8021.511 | N6: =M6/M33 -> 9220.1276 | O6: =$C$17*E6*M42 -> 320.76 | P6: =$C$17*E6*M51 -> 2138.4 | Q6: =P6+O6 -> 2459.16 | R6: =M60 -> 6000 | S6: =(R6+(P6+O6)*$C$16)/1000 -> 55.1832 | U6: =F21*E6 -> 0.0972 | V6: =$C$17*U6 -> 1458 | W6: =Dati!D70 -> 0.065 | X6: =W6*$C$17 -> 975 | Y6: =Z6/$C$16 -> 2250 | Z6: =G65 -> 45000 | AA6: =AB6/$C$16 -> 4683 | AB6: =(X6+V6)*$C$16+Z6 -> 93660
B7: Elettrico rete | C7: =C48 -> 59.5 | D7: =D48 -> 435.69079 | E7: =F48 -> 0.13666667 | G7: =H7/M34 -> 119 | H7: =C7 -> 59.5 | I7: =H7*N34 -> 53.55 | J7: =I7/G7 -> 0.45 | L7: =C17*E48 -> 2050 | M7: =$C$17*E7 -> 2050 | N7: =M7/M34 -> 4100 | O7: =$C$17*E7*$M$43 -> 440.75 | P7: =$C$17*E7*M52 -> 0 | Q7: =P7+O7 -> 440.75 | R7: =M61 -> 12000 | S7: =(R7+(P7+O7)*$C$16)/1000 -> 20.815 | U7: =F22*E7 -> 0.042366667 | V7: =$C$17*U7 -> 635.5 | W7: =Dati!$D$71 -> 0.03 | X7: =W7*$C$17 -> 450 | Y7: =Z7/$C$16 -> 1916.6667 | Z7: =G48 -> 38333.333 | AA7: =AB7/$C$16 -> 3002.1667 | AB7: =(X7+V7)*$C$16+Z7 -> 60043.333
B8: Elettrico autoprodotto | C8: =C48 -> 59.5 | D8: =D48 -> 435.69079 | E8: =F48 -> 0.13666667 | G8: =H8/M35 -> 66.111111 | H8: =C8 -> 59.5 | I8: =H8*N35 -> 53.55 | J8: =I8/G8 -> 0.81 | L8: =C17*E48 -> 2050 | M8: =$C$17*E8 -> 2050 | N8: =M8/M35 -> 2277.7778 | O8: =$C$17*E8*M44 -> 112.75 | P8: =$C$17*E8*M53 -> 0 | Q8: =P8+O8 -> 112.75 | R8: =M61 -> 12000 | S8: =(R8+(P8+O8)*$C$16)/1000 -> 14.255 | U8: =F23*E8 -> 0.0328 | V8: =$C$17*U8 -> 492 | W8: =Dati!$D$71 -> 0.03 | X8: =W8*$C$17 -> 450 | Y8: =Z8/$C$16 -> 1916.6667 | Z8: =G48 -> 38333.333 | AA8: =AB8/$C$16 -> 2858.6667 | AB8: =(X8+V8)*$C$16+Z8 -> 57173.333
B9: Idrogeno Grigio | C9: =C56 -> 5.965 | D9: =D56 -> 702.36711 | E9: =F57 -> 0.3333 | G9: =H9/M36 -> 284.01921 | H9: =C9*Dati!$F$5 -> 198.81345 | I9: =H9*N36 -> 89.466053 | J9: =I9/G9 -> 0.315 | L9: =C17*E57 -> 150 | M9: =$C$17*E9 -> 4999.5 | N9: =M9/M36 -> 7142.1429 | O9: =$C$17*E9*M45 -> 1650 | P9: =$C$17*E9*M54 -> 0 | Q9: =P9+O9 -> 1650 | R9: =M62 -> 14000 | S9: =(R9+(P9+O9)*$C$16)/1000 -> 47 | U9: =F24*E9 -> 0.02 | V9: =$C$17*U9 -> 300 | W9: =Dati!$D$72 -> 0.055 | X9: =W9*$C$17 -> 825 | Y9: =Z9/$C$16 -> 3375 | Z9: =G56 -> 67500 | AA9: =AB9/$C$16 -> 4500 | AB9: =(X9+V9)*$C$16+Z9 -> 90000
B10: Idrogeno rete | C10: =C56 -> 5.965 | D10: =D56 -> 702.36711 | E10: =F57 -> 0.3333 | G10: =H10/M37 -> 722.958 | H10: =C10*Dati!$F$5 -> 198.81345 | I10: =H10*N37 -> 89.466053 | J10: =I10/G10 -> 0.12375 | L10: =C17*E57 -> 150 | M10: =$C$17*E10 -> 4999.5 | N10: =M10/M37 -> 18180 | O10: =$C$17*E10*M46 -> 1935 | P10: =$C$17*E10*M55 -> 0 | Q10: =P10+O10 -> 1935 | R10: =M62 -> 14000 | S10: =(R10+(P10+O10)*$C$16)/1000 -> 52.7 | U10: =F25*E10 -> 0.2 | V10: =$C$17*U10 -> 3000 | W10: =Dati!$D$72 -> 0.055 | X10: =W10*$C$17 -> 825 | Y10: =Z10/$C$16 -> 3375 | Z10: =G56 -> 67500 | AA10: =AB10/$C$16 -> 7200 | AB10: =(X10+V10)*$C$16+Z10 -> 144000
B11: Idrogeno autoprodotto | C11: =C56 -> 5.965 | D11: =D56 -> 702.36711 | E11: =F57 -> 0.3333 | G11: =H11/M38 -> 320.66685 | H11: =C11*Dati!$F$5 -> 198.81345 | I11: =H11*N38 -> 89.466053 | J11: =I11/G11 -> 0.279 | L11: =C17*E57 -> 150 | M11: =$C$17*E11 -> 4999.5 | N11: =M11/M38 -> 8063.7097 | O11: =$C$17*E11*M47 -> 450 | P11: =$C$17*E11*M56 -> 0 | Q11: =P11+O11 -> 450 | R11: =M62 -> 14000 | S11: =(R11+(P11+O11)*$C$16)/1000 -> 23 | U11: =F26*E11 -> 0.15 | V11: =$C$17*U11 -> 2250 | W11: =Dati!$D$72 -> 0.055 | X11: =W11*$C$17 -> 825 | Y11: =Z11/$C$16 -> 3375 | Z11: =G56 -> 67500 | AA11: =AB11/$C$16 -> 6450 | AB11: =(X11+V11)*$C$16+Z11 -> 129000
B14: Assunzioni: | H14: IPOTESI:
B15: Utilizzo | C15: =C16*C17 -> 300000 | D15: km | H15: Parametri uniformi (C15, C16, C17) per mezzo a prescindere dal vettore energetico per rendere paragonabile il confronto
B16: Lifetime | C16: 20 | D16: y | F16: [y]
B17: Percorso | C17: =D17*100 -> 15000 | D17: 150 | F17: [km/y]
B19: COSTI FUEL
B20: Benzina | C20: =Dati!B12 -> 1.9 | D20: [€/l] | E20: --> | F20: =Dati!G12 -> 0.21708083 | G20: [€/kWh]
B21: Diesel | C21: =Dati!B13 -> 1.8 | D21: [€/l] | E21: --> | F21: =Dati!G13 -> 0.18176127 | G21: [€/kWh] | I21: Scenario 1: Utente con Ricarica Casa dalla RETE | O21: 0.31 | P21: [€/kWh]
B22: Elettrico rete | C22: =Dati!B14 -> 0.31 | D22: [€/kWh] | E22: --> | F22: =Dati!G14 -> 0.31 | G22: [€/kWh] | I22: Scenario 2: Utente con Ricarica Casa FOTOVOLTAICO (Autoprodotta) | O22: 0.24 | P22: [€/kWh]
B23: Elettrico autoprodotto | C23: =Dati!B15 -> 0.24 | D23: [€/kWh] | E23: --> | F23: =Dati!G15 -> 0.24 | G23: [€/kWh] | I23: Scenario 3: Utente SENZA Ricarica Casa (solo pubblico) | O23: 0.56 | P23: [€/kWh]
B24: Idrogeno grigio | C24: =Dati!B16 -> 2 | D24: [€/kg] | E24: --> | F24: =Dati!G16 -> 0.060006001 | G24: [€/kWh]
B25: Idrogeno elettrolisi rete | C25: =Dati!B17 -> 20 | D25: [€/kg] | E25: --> | F25: =Dati!G17 -> 0.60006001 | G25: [€/kWh]
B26: Idrogeno Verde elettrolisi PV | C26: =Dati!B18 -> 15 | D26: [€/kg] | E26: --> | F26: =Dati!G18 -> 0.450045 | G26: [€/kWh]
B31: BENZINA | L31: Parametro | M31: Ƞ_WtT | N31: Ƞ_TtW | O31: Ƞ_WtW | S31: OPEx | Y31: USATO DATI AL KM
B32: Modello | C32: Serbatoio | D32: Autonomia | E32: Consumo | G32: Costo | H32: Note | L32: Benzina | M32: =Dati!Z11 -> 0.85 | N32: =Dati!Z23 -> 0.25 | O32: =M32*N32 -> 0.2125 | S32: AUTOMOBILE | T32: Benzina | U32: Diesel | V32: Elettrica (BEV) | W32: Idrogeno (FCEV)
C33: [l] | D33: [km] | E33: [l/km] | F33: [kWh/km] | G33: [€] | L33: Diesel | M33: =Dati!Z12 -> 0.87 | N33: =Dati!Z24 -> 0.32 | O33: =N33*M33 -> 0.2784 | S33: Manutenzione Ordinaria (tagliandi, filtri, liquidi) | T33: 5000 | U33: 5500 | V33: 2000 | W33: 3500
B34: MG 5 (Cina) | C34: 50 | D34: =C34/E34 -> 746.26866 | E34: 0.067 | F34: =E34*Dati!$G$3 -> 0.5864175 | G34: 25000 | H34: Station wagon, ottimo valore | L34: Elettrico Rete | M34: =Dati!Z13 -> 0.5 | N34: =Dati!Z25 -> 0.9 | O34: =M34*N34 -> 0.45 | S34: Freni (pastiglie, dischi) | T34: 1400 | U34: 1400 | V34: 600 | W34: 800
B35: Volkswagen Golf | C35: 54 | D35: =C35/E35 -> 805.97015 | E35: 0.067 | F35: =E35*Dati!$G$3 -> 0.5864175 | G35: 33000 | L35: Elettrico FV | M35: =Dati!Z14 -> 0.9 | N35: =Dati!Z25 -> 0.9 | O35: =M35*N35 -> 0.81 | S35: Batteria di Trazione (sostituzione) | T35: - | U35: - | V35: 4000
B36: Audi A4 | C36: 54 | D36: =C36/E36 -> 857.14286 | E36: 0.063 | F36: =E36*Dati!$G$3 -> 0.5514075 | G36: 48000 | L36: Idrogeno Grigio (SMR) | M36: =Dati!Z15 -> 0.7 | N36: =Dati!Z26 -> 0.45 | O36: =M36*N36 -> 0.315 | S36: Batteria 12V (sostituzioni) | T36: 400 | U36: 400 | V36: 300 | W36: 400
B37: BMW X3 | C37: 65 | D37: =C37/E37 -> 902.77778 | E37: 0.072 | F37: =E37*Dati!$G$3 -> 0.63018 | G37: 58000 | L37: Idrogeno da Rete (Elettrolisi) | M37: =Dati!Z16 -> 0.275 | N37: =Dati!Z26 -> 0.45 | O37: =M37*N37 -> 0.12375 | S37: Cella a Combustibile (sostituzione) | T37: - | U37: - | V37: - | W37: 25000
B38: Media | C38: =AVERAGE(C34:C37) -> 55.75 | D38: =AVERAGE(D34:D37) -> 828.03986 | E38: =AVERAGE(E34:E37) -> 0.06725 | F38: =AVERAGE(F34:F37) -> 0.58860563 | G38: =AVERAGE(G34:G37) -> 41000 | L38: Idrogeno da FV (Elettrolisi) | M38: =Dati!Z17 -> 0.62 | N38: =Dati!Z26 -> 0.45 | O38: =M38*N38 -> 0.279 | S38: Altri Componenti (frizione, scarico, turbina, ecc.) | T38: 3000 | U38: =(2500+5000)/2 -> 3750 | V38: 1000 | W38: 1500
S39: TOTALE STIMATO | T39: =SUM(T33:T38) -> 9800 | U39: =SUM(U33:U38) -> 11050 | V39: =SUM(V33:V38) -> 7900 | W39: =SUM(W33:W38) -> 31200
B40: BEV | L40: Emissioni CO2 WtT
B41: Modello | C41: Serbatoio | D41: Autonomia | E41: Consumo | G41: Costo | H41: Note | L41: Benzina | M41: =Dati!R28 -> 0.065981148 | N41: [kg CO2/kWh] | P41: 0.25 | Q41: [kg CO₂/kWh] | R41: rispetto a TTW
C42: [kWh] | D42: [km] | E42: [kWh/km] | F42: [kWh/km] | G42: [€] | L42: Diesel | M42: =Dati!R29 -> 0.039987479 | N42: [kg CO2/kWh] | P42: 0.15 | Q42: [kg CO₂/kWh] | R42: rispetto a TTW
B43: BYD Dolphin (Cina) | C43: 60.5 | D43: =C43/E43 -> 426.05634 | E43: 0.142 | F43: =E43 -> 0.142 | G43: 35000 | H43: Compatta, leader di mercato | L43: Elettricità Mix ITA | M43: =Dati!R30 -> 0.215 | N43: [kg CO₂/kWh]
B44: Volkswagen ID.3 | C44: 58 | D44: =C44/E44 -> 426.47059 | E44: 0.136 | F44: =E44 -> 0.136 | G44: 38000 | L44: Elettricità da FV | M44: =Dati!R31 -> 0.055 | N44: [kg CO₂/kWh]
B45: Tesla Model 3 | C45: 60 | D45: =C45/E45 -> 454.54545 | E45: 0.132 | F45: =E45 -> 0.132 | G45: 42000 | L45: Idrogeno SMR | M45: =Dati!R32 -> 0.330033 | N45: [kg CO₂/kWh]
B46: Zeekr 001 (Cina) | C46: 140 | D46: =C46/E46 -> 903.22581 | E46: 0.155 | F46: =E46 -> 0.155 | G46: 65000 | H46: Station wagon premium | L46: Idrogeno (da elettrolisi con Rete IT) | M46: =Dati!R33 -> 0.3870387 | N46: [kg CO₂/kWh]
B47: Audi Q8 e-tron | C47: 114 | D47: =C47/E47 -> 600 | E47: 0.19 | F47: =E47 -> 0.19 | G47: 85000 | L47: Idrogeno (da elettrolisi con PV) | M47: =Dati!R34 -> 0.090009001 | N47: [kg CO₂/kWh] | P47: oppure | Q47: 3 | R47: [kgCO2/kgH2]
B48: Media | C48: =AVERAGE(C43:C45) -> 59.5 | D48: =AVERAGE(D43:D45) -> 435.69079 | E48: =AVERAGE(E43:E45) -> 0.13666667 | F48: =AVERAGE(F43:F45) -> 0.13666667 | G48: =AVERAGE(G43:G45) -> 38333.333
...

Sheet CAMION
C2: DATI "TARGA" | G2: ENERGIA CONTENUTA | L2: ENERGIA & EMISSIONI ANNO TIPO | U2: COSTI
C3: Serbatoio | D3: Autonomia | E3: Consumo | G3: Well | H3: Tank | I3: Wheel | J3: η_WtW | L3: Carburante | M3: Energia Utile | N3: Energia primaria richiesta | O3: Emissioni CO2 - 170.000 km | Q3: Emissioni totale carburante | R3: Emissioni costruzione | S3: Emissioni Totali | U3: OPEx fuel | W3: OPEx Maintenance | Y3: CAPEx | AA3: Costo totale
C4: [l/kWh/kg] | D4: [km] | E4: [kWh/km] | G4: [kWh] | H4: [kWh] | I4: [kWh] | J4: [ - ] | L4: [l/kWh/kg] | M4: [kWh] | N4: [kWh] | O4: WtT - [kgCO2/anno] | P4: TtW [kgCO2/anno] | Q4: [tCO2/anno] | R4: [kg/CO2] | S4: [t CO2] | U4: [€/km] | V4: [€/anno] | W4: [€/km] | X4: [€/anno] | Y4: [€/anno] | Z4: [€] | AA4: [€/anno] | AB4: [€]
B5: Diesel | C5: =C34 -> 866.66667 | D5: =H5/E5 -> 2626.2626 | E5: =F34 -> 3.268023 | G5: =H5/N29 -> 9865.1571 | H5: =C5*Dati!G4 -> 8582.6867 | I5: =H5*O29 -> 3433.0747 | J5: =I5/G5 -> 0.348 | L5: =C16*E34 -> 56100 | M5: =$C$16*E5 -> 555563.91 | N5: =M5/N29 -> 638579.21 | O5: =M5*N37 -> 22215.6 | P5: =M5*N45 -> 148104 | Q5: =(O5+P5)/1000 -> 170.3196 | R5: =N52 -> 60000 | S5: =(R5+(P5+O5)*$C$15)/1000 -> 1252.2372 | U5: =F19*E5 -> 0.594 | V5: =U5*$C$16 -> 100980 | W5: =Dati!D73 -> 0.25 | X5: =W5*$C$16 -> 42500 | Y5: =Z5/$C$15 -> 16428.571 | Z5: =G34 -> 115000 | AA5: =AB5/$C$15 -> 159908.57 | AB5: =((X5+V5)*$C$15+Z5) -> 1119360
B6: Elettrico rete | C6: =C44 -> 519 | D6: =H6/E6 -> 330.04769 | E6: =F44 -> 1.5725 | G6: =H6/N30 -> 1038 | H6: =C6 -> 519 | I6: =H6*O30 -> 441.15 | J6: =I6/G6 -> 0.425 | L6: =$C$16*$F$44 -> 267325 | M6: =$C$16*E6 -> 267325 | N6: =M6/N30 -> 534650 | O6: =M6*N38 -> 57474.875 | P6: 0 | Q6: =(O6+P6)/1000 -> 57.474875 | R6: =N53 -> 110000 | S6: =(R6+(P6+O6)*$C$15)/1000 -> 512.32412 | U6: =F20*E6 -> 0.487475 | V6: =U6*$C$16 -> 82870.75 | W6: =Dati!$D$74 -> 0.14 | X6: =W6*$C$16 -> 23800 | Y6: =Z6/$C$15 -> 35000 | Z6: =$G$44 -> 245000 | AA6: =AB6/$C$15 -> 141670.75 | AB6: =((X6+V6)*$C$15+Z6) -> 991695.25
B7: Elettrico autoprodotto | C7: =C44 -> 519 | D7: =H7/E7 -> 330.04769 | E7: =F44 -> 1.5725 | G7: =H7/N31 -> 576.66667 | H7: =C7 -> 519 | I7: =H7*O31 -> 441.15 | J7: =I7/G7 -> 0.765 | L7: =$C$16*$F$44 -> 267325 | M7: =$C$16*E7 -> 267325 | N7: =M7/N31 -> 297027.78 | O7: =M7*N39 -> 14702.875 | P7: 0 | Q7: =(O7+P7)/1000 -> 14.702875 | R7: =N53 -> 110000 | S7: =(R7+(P7+O7)*$C$15)/1000 -> 212.92012 | U7: =F21*E7 -> 0.3774 | V7: =U7*$C$16 -> 64158 | W7: =Dati!$D$74 -> 0.14 | X7: =W7*$C$16 -> 23800 | Y7: =Z7/$C$15 -> 35000 | Z7: =$G$44 -> 245000 | AA7: =AB7/$C$15 -> 122958 | AB7: =((X7+V7)*$C$15+Z7) -> 860706
B8: Idrogeno Grigio | C8: =C52 -> 50.333333 | D8: =H8/E8 -> 598.0198 | E8: =F52 -> 2.805275 | G8: =H8/N32 -> 2396.5857 | H8: =C8*Dati!$F$5 -> 1677.61 | I8: =H8*O32 -> 721.3723 | J8: =I8/G8 -> 0.301 | L8: =$C$16*$E$52 -> 14308.333 | M8: =$C$16*E8 -> 476896.75 | N8: =M8/N32 -> 681281.07 | O8: =M8*N40 -> 157391.67 | P8: =$C$16*E8*M49 -> 0 | Q8: =(O8+P8)/1000 -> 157.39167 | R8: =N54 -> 125000 | S8: =(R8+(P8+O8)*$C$15)/1000 -> 1226.7417 | U8: =F22*E8 -> 0.16833333 | V8: =U8*$C$16 -> 28616.667 | W8: =Dati!$D$75 -> 0.2 | X8: =W8*$C$16 -> 34000 | Y8: =Z8/$C$15 -> 57142.857 | Z8: =$G$52 -> 400000 | AA8: =AB8/$C$15 -> 119759.52 | AB8: =((X8+V8)*$C$15+Z8) -> 838316.67
B9: Idrogeno rete | C9: =C52 -> 50.333333 | D9: =H9/E9 -> 598.0198 | E9: =F52 -> 2.805275 | G9: =H9/N33 -> 6100.4 | H9: =C9*Dati!$F$5 -> 1677.61 | I9: =H9*O33 -> 721.3723 | J9: =I9/G9 -> 0.11825 | L9: =$C$16*$E$52 -> 14308.333 | M9: =$C$16*E9 -> 476896.75 | N9: =M9/N33 -> 1734170 | O9: =M9*N41 -> 184577.5 | P9: 0 | Q9: =(O9+P9)/1000 -> 184.5775 | R9: =N54 -> 125000 | S9: =(R9+(P9+O9)*$C$15)/1000 -> 1417.0425 | U9: =F23*E9 -> 1.6833333 | V9: =U9*$C$16 -> 286166.67 | W9: =Dati!$D$75 -> 0.2 | X9: =W9*$C$16 -> 34000 | Y9: =Z9/$C$15 -> 57142.857 | Z9: =$G$52 -> 400000 | AA9: =AB9/$C$15 -> 377309.52 | AB9: =((X9+V9)*$C$15+Z9) -> 2641166.7
B10: Idrogeno autoprodotto | C10: =C52 -> 50.333333 | D10: =H10/E10 -> 598.0198 | E10: =F52 -> 2.805275 | G10: =H10/N34 -> 2705.8226 | H10: =C10*Dati!$F$5 -> 1677.61 | I10: =H10*O34 -> 721.3723 | J10: =I10/G10 -> 0.2666 | L10: =$C$16*$E$52 -> 14308.333 | M10: =$C$16*E10 -> 476896.75 | N10: =M10/N34 -> 769188.31 | O10: =M10*N42 -> 42925 | P10: 0 | Q10: =(O10+P10)/1000 -> 42.925 | R10: =N54 -> 125000 | S10: =(R10+(P10+O10)*$C$15)/1000 -> 425.475 | U10: =F24*E10 -> 1.2625 | V10: =U10*$C$16 -> 214625 | W10: =Dati!$D$75 -> 0.2 | X10: =W10*$C$16 -> 34000 | Y10: =Z10/$C$15 -> 57142.857 | Z10: =$G$52 -> 400000 | AA10: =AB10/$C$15 -> 305767.86 | AB10: =((X10+V10)*$C$15+Z10) -> 2140375
B13: Assunzioni: | H13: IPOTESI:
B14: Utilizzo | C14: =C15*C16 -> 1190000 | D14: km | H14: Parametri uniformi (C14, C15, C16) per mezzo a prescindere dal vettore energetico per rendere paragonabile il confronto
B15: Lifetime | C15: 7 | D15: y | F15: [y]
B16: Percorso | C16: =D16*100 -> 170000 | D16: 1700 | F16: [km/y]
B18: COSTI FUEL
B19: Diesel | C19: =Dati!B13 -> 1.8 | D19: [€/l] | E19: --> | F19: =Dati!G13 -> 0.18176127 | G19: [€/kWh] | I19: Scenario 1: Utente con Ricarica Casa dalla RETE | O19: 0.31 | P19: [€/kWh]
B20: Elettrico rete | C20: =Dati!B14 -> 0.31 | D20: [€/kWh] | E20: --> | F20: =Dati!G14 -> 0.31 | G20: [€/kWh] | I20: Scenario 2: Utente con Ricarica Casa FOTOVOLTAICO (Autoprodotta) | O20: 0.24 | P20: [€/kWh]
B21: Elettrico autoprodotto | C21: =Dati!B15 -> 0.24 | D21: [€/kWh] | E21: --> | F21: =Dati!G15 -> 0.24 | G21: [€/kWh] | I21: Scenario 3: Utente SENZA Ricarica Casa (solo pubblico) | O21: 0.56 | P21: [€/kWh]
B22: Idrogeno grigio | C22: =Dati!B16 -> 2 | D22: [€/kg] | E22: --> | F22: =Dati!G16 -> 0.060006001 | G22: [€/kWh]
B23: Idrogeno elettrolisi rete | C23: =Dati!B17 -> 20 | D23: [€/kg] | E23: --> | F23: =Dati!G17 -> 0.60006001 | G23: [€/kWh]
B24: Idrogeno Verde elettrolisi PV | C24: =Dati!B18 -> 15 | D24: [€/kg] | E24: --> | F24: =Dati!G18 -> 0.450045 | G24: [€/kWh]
B28: Diesel | M28: Parametro | N28: Ƞ_WtT | O28: Ƞ_TtW | P28: Ƞ_WtW
B29: Modello | C29: Serbatoio | D29: Autonomia | E29: Consumo | G29: Costo | H29: Note | M29: Diesel | N29: =Dati!Z12 -> 0.87 | O29: =Dati!AA24 -> 0.4 | P29: =N29*O29 -> 0.348
C30: [l] | D30: [km] | E30: [l/km] | F30: [kWh/km] | G30: [€] | M30: Elettrico Rete | N30: =Dati!Z13 -> 0.5 | O30: =Dati!AA25 -> 0.85 | P30: =N30*O30 -> 0.425
B31: FAW J7 (Cina) | C31: 1000 | D31: =C31/E31 -> 3030.303 | E31: 0.33 | F31: =E31*Dati!$G$4 -> 3.268023 | G31: 80000 | H31: Leader mercato cinese | M31: Elettrico FV | N31: =Dati!Z14 -> 0.9 | O31: =Dati!AA25 -> 0.85 | P31: =N31*O31 -> 0.765
B32: Volvo FH | C32: 800 | D32: =C32/E32 -> 2424.2424 | E32: 0.33 | F32: =E32*Dati!$G$4 -> 3.268023 | G32: 130000 | M32: Idrogeno Grigio (SMR) | N32: =Dati!Z15 -> 0.7 | O32: =Dati!AA26 -> 0.43 | P32: =N32*O32 -> 0.301
B33: Mercedes Actros | C33: 800 | D33: =C33/E33 -> 2424.2424 | E33: 0.33 | F33: =E33*Dati!$G$4 -> 3.268023 | G33: 135000 | M33: Idrogeno da Rete (Elettrolisi) | N33: =Dati!Z16 -> 0.275 | O33: =Dati!AA26 -> 0.43 | P33: =N33*O33 -> 0.11825
B34: Media | C34: =AVERAGE(C31:C33) -> 866.66667 | D34: =AVERAGE(D31:D33) -> 2626.2626 | E34: =AVERAGE(E31:E33) -> 0.33 | F34: =AVERAGE(F31:F33) -> 3.268023 | G34: =AVERAGE(G31:G33) -> 115000 | M34: Idrogeno da FV (Elettrolisi) | N34: =Dati!Z17 -> 0.62 | O34: =Dati!AA26 -> 0.43 | P34: =N34*O34 -> 0.2666
M36: Emissioni CO2 WtT
B37: Elettrico (BEV) | M37: Diesel | N37: =Dati!R29 -> 0.039987479 | O37: [kg CO2/kWh] | Q37: 0.15 | R37: [kg CO₂/kWh] | S37: rispetto a TTW
B38: Modello | C38: Serbatoio | D38: Autonomia | E38: Consumo | G38: Costo | H38: Note | M38: Elettricità Mix ITA | N38: =Dati!R30 -> 0.215 | O38: [kg CO₂/kWh]
C39: [kWh] | D39: [km] | E39: [kWh/km] | F39: [kWh/km] | G39: [€] | M39: Elettricità da FV | N39: =Dati!R31 -> 0.055 | O39: [kg CO₂/kWh]
B40: SANY EVI568 (Cina) | C40: 350 | D40: =C40/E40 -> 200 | E40: 1.75 | F40: =E40 -> 1.75 | G40: 180000 | H40: Prezzo molto competitivo | M40: Idrogeno SMR | N40: =Dati!R32 -> 0.330033 | O40: [kg CO₂/kWh]
B41: Mercedes eActros | C41: 336 | D41: =C41/E41 -> 200 | E41: 1.68 | F41: =E41 -> 1.68 | G41: 250000 | M41: Idrogeno (da elettrolisi con Rete IT) | N41: =Dati!R33 -> 0.3870387 | O41: [kg CO₂/kWh]
B42: Volvo FH Electric | C42: 540 | D42: =C42/E42 -> 300 | E42: 1.8 | F42: =E42 -> 1.8 | G42: 300000 | M42: Idrogeno (da elettrolisi con PV) | N42: =Dati!R34 -> 0.090009001 | O42: [kg CO₂/kWh] | Q42: oppure | R42: 3 | S42: [kgCO2/kgH2]
B43: Tesla Semi | C43: 850 | D43: =C43/E43 -> 801.88679 | E43: 1.06 | F43: =E43 -> 1.06 | G43: 250000
B44: Media | C44: =AVERAGE(C40:C43) -> 519 | D44: =AVERAGE(D40:D43) -> 375.4717 | E44: =AVERAGE(E40:E43) -> 1.5725 | F44: =AVERAGE(F40:F43) -> 1.5725 | G44: =AVERAGE(G40:G43) -> 245000 | M44: Emissioni CO2 TtW
M45: Diesel | N45: =Dati!R40 -> 0.26658319 | O45: [kg CO2/kWh]
B46: Idrogeno (FCEV) | M46: Elettricità Mix ITA | N46: 0 | O46: [kg CO₂/kWh] | T46: LIFETIME
B47: Modello | C47: Serbatoio | D47: Autonomia | E47: Consumo | G47: Costo | H47: Pressione | M47: Elettricità da FV | N47: 0 | O47: [kg CO₂/kWh] | T47: Categoria Veicolo | U47: Alimentazione | V47: Vita Utile [km] | W47: Vita Utile [anni] | X47: Percorso Medio
C48: [kg] | D48: [km] | E48: [kg/km] | F48: [kWh/km] | G48: [€] | H48: [bar] | I48: Note | M48: Idrogeno (da elettrolisi con PV) | N48: 0 | O48: [kg CO₂/kWh] | T48: Camion (Trattore Stradale 40t) | U48: Diesel | V48: =(1200000 +1600000)/2 -> 1400000 | W48: =13/2 -> 6.5 | X48: 200000
...

Sheet AUTOBUS Urbano
C2: DATI "TARGA" | G2: ENERGIA CONTENUTA | L2: ENERGIA & EMISSIONI ANNO TIPO | U2: COSTI
C3: Serbatoio | D3: Autonomia | E3: Consumo | G3: Well | H3: Tank | I3: Wheel | J3: η_WtW | L3: Carburante | M3: Energia Utile | N3: Energia primaria richiesta | O3: Emissioni CO2 - 170.000 km | Q3: Emissioni totale carburante | R3: Emissioni costruzione | S3: Emissioni Totali | U3: OPEx fuel | W3: OPEx Maintenance | Y3: CAPEx | AA3: Costo totale
C4: [l/kWh/kg] | D4: [km] | E4: [kWh/km] | G4: [kWh] | H4: [kWh] | I4: [kWh] | J4: [ - ] | L4: [l/kWh/kg] | M4: [kWh] | N4: [kWh] | O4: WtT - [kgCO2/anno] | P4: TtW [kgCO2/anno] | Q4: [tCO2/anno] | R4: [kg/CO2] | S4: [t CO2] | U4: [€/km] | V4: [€/anno] | W4: [€/km] | X4: [€/anno] | Y4: [€/anno] | Z4: [€] | AA4: [€/anno] | AB4: [€]
B5: Diesel | C5: =C34 -> 295 | D5: =H5/E5 -> 762.93103 | E5: =F34 -> 3.8291987 | G5: =H5/N29 -> 3357.9477 | H5: =C5*Dati!G4 -> 2921.4145 | I5: =H5*O29 -> 876.42435 | J5: =I5/G5 -> 0.261 | L5: =C16*E34 -> 27066.667 | M5: =$C$16*E5 -> 268043.91 | N5: =M5/N29 -> 308096.44 | O5: =M5*N37 -> 10718.4 | P5: =M5*N45 -> 71456 | Q5: =(O5+P5)/1000 -> 82.1744 | R5: =N53 -> 50000 | S5: =(R5+(P5+O5)*$C$15)/1000 -> 1118.2672 | U5: =F19*E5 -> 0.696 | V5: =U5*$C$16 -> 48720 | W5: =Dati!$D$76 -> 0.325 | X5: =W5*$C$16 -> 22750 | Y5: =Z5/$C$15 -> 16410.256 | Z5: =G34 -> 213333.33 | AA5: =AB5/$C$15 -> 87880.256 | AB5: =((X5+V5)*$C$15+Z5) -> 1142443.3
B6: Elettrico rete | C6: =C44 -> 347.5 | D6: =H6/E6 -> 207.1535 | E6: =$F$44 -> 1.6775 | G6: =H6/N30 -> 695 | H6: =C6 -> 347.5 | I6: =H6*O30 -> 278 | J6: =I6/G6 -> 0.4 | L6: =$C$16*$F$43 -> 161000 | M6: =$C$16*E6 -> 117425 | N6: =M6/N30 -> 234850 | O6: =M6*N38 -> 25246.375 | P6: 0 | Q6: =(O6+P6)/1000 -> 25.246375 | R6: =$N$54 -> 85000 | S6: =(R6+(P6+O6)*$C$15)/1000 -> 413.20288 | U6: =F20*E6 -> 0.520025 | V6: =U6*$C$16 -> 36401.75 | W6: =Dati!$D$77 -> 0.16 | X6: =W6*$C$16 -> 11200 | Y6: =Z6/$C$15 -> 30576.923 | Z6: =$G$44 -> 397500 | AA6: =AB6/$C$15 -> 78178.673 | AB6: =((X6+V6)*$C$15+Z6) -> 1016322.8
B7: Elettrico autoprodotto | C7: =C44 -> 347.5 | D7: =H7/E7 -> 207.1535 | E7: =$F$44 -> 1.6775 | G7: =H7/N31 -> 386.11111 | H7: =C7 -> 347.5 | I7: =H7*O31 -> 278 | J7: =I7/G7 -> 0.72 | L7: =$C$16*$F$43 -> 161000 | M7: =$C$16*E7 -> 117425 | N7: =M7/N31 -> 130472.22 | O7: =M7*N39 -> 6458.375 | P7: 0 | Q7: =(O7+P7)/1000 -> 6.458375 | R7: =$N$54 -> 85000 | S7: =(R7+(P7+O7)*$C$15)/1000 -> 168.95888 | U7: =F21*E7 -> 0.4026 | V7: =U7*$C$16 -> 28182 | W7: =Dati!$D$77 -> 0.16 | X7: =W7*$C$16 -> 11200 | Y7: =Z7/$C$15 -> 30576.923 | Z7: =$G$44 -> 397500 | AA7: =AB7/$C$15 -> 69958.923 | AB7: =((X7+V7)*$C$15+Z7) -> 909466
B8: Idrogeno Grigio | C8: =$C$53 -> 34.166667 | D8: =H8/E8 -> 354.67128 | E8: =$F$53 -> 3.21079 | G8: =H8/N32 -> 1626.8214 | H8: =C8*Dati!$F$5 -> 1138.775 | I8: =H8*O32 -> 569.3875 | J8: =I8/G8 -> 0.35 | L8: =$C$16*$E$53 -> 6743.3333 | M8: =$C$16*E8 -> 224755.3 | N8: =M8/N32 -> 321079 | O8: =M8*N40 -> 74176.667 | P8: 0 | Q8: =(O8+P8)/1000 -> 74.176667 | R8: =$N$55 -> 95000 | S8: =(R8+(P8+O8)*$C$15)/1000 -> 1059.2967 | U8: =F22*E8 -> 0.19266667 | V8: =U8*$C$16 -> 13486.667 | W8: =Dati!$D$78 -> 0.275 | X8: =W8*$C$16 -> 19250 | Y8: =Z8/$C$15 -> 43589.744 | Z8: =$G$53 -> 566666.67 | AA8: =AB8/$C$15 -> 76326.41 | AB8: =((X8+V8)*$C$15+Z8) -> 992243.33
B9: Idrogeno rete | C9: =$C$53 -> 34.166667 | D9: =H9/E9 -> 354.67128 | E9: =$F$53 -> 3.21079 | G9: =H9/N33 -> 4141 | H9: =C9*Dati!$F$5 -> 1138.775 | I9: =H9*O33 -> 569.3875 | J9: =I9/G9 -> 0.1375 | L9: =$C$16*$E$53 -> 6743.3333 | M9: =$C$16*E9 -> 224755.3 | N9: =M9/N33 -> 817292 | O9: =M9*N41 -> 86989 | P9: 0 | Q9: =(O9+P9)/1000 -> 86.989 | R9: =$N$55 -> 95000 | S9: =(R9+(P9+O9)*$C$15)/1000 -> 1225.857 | U9: =F23*E9 -> 1.9266667 | V9: =U9*$C$16 -> 134866.67 | W9: =Dati!$D$78 -> 0.275 | X9: =W9*$C$16 -> 19250 | Y9: =Z9/$C$15 -> 43589.744 | Z9: =$G$53 -> 566666.67 | AA9: =AB9/$C$15 -> 197706.41 | AB9: =((X9+V9)*$C$15+Z9) -> 2570183.3
B10: Idrogeno autoprodotto | C10: =$C$53 -> 34.166667 | D10: =H10/E10 -> 354.67128 | E10: =$F$53 -> 3.21079 | G10: =H10/N34 -> 1836.7339 | H10: =C10*Dati!$F$5 -> 1138.775 | I10: =H10*O34 -> 569.3875 | J10: =I10/G10 -> 0.31 | L10: =$C$16*$E$53 -> 6743.3333 | M10: =$C$16*E10 -> 224755.3 | N10: =M10/N34 -> 362508.55 | O10: =M10*N42 -> 20230 | P10: 0 | Q10: =(O10+P10)/1000 -> 20.23 | R10: =$N$55 -> 95000 | S10: =(R10+(P10+O10)*$C$15)/1000 -> 357.99 | U10: =F24*E10 -> 1.445 | V10: =U10*$C$16 -> 101150 | W10: =Dati!$D$78 -> 0.275 | X10: =W10*$C$16 -> 19250 | Y10: =Z10/$C$15 -> 43589.744 | Z10: =$G$53 -> 566666.67 | AA10: =AB10/$C$15 -> 163989.74 | AB10: =((X10+V10)*$C$15+Z10) -> 2131866.7
B13: Assunzioni: | H13: IPOTESI:
B14: Utilizzo | C14: =C15*C16 -> 910000 | D14: km | H14: Parametri uniformi (C14, C15, C16) per mezzo a prescindere dal vettore energetico per rendere paragonabile il confronto
B15: Lifetime | C15: =D15 -> 13 | D15: 13 | F15: [y]
B16: Percorso | C16: =D16*100 -> 70000 | D16: 700 | F16: [km/y]
B18: COSTI FUEL
B19: Diesel | C19: =Dati!B13 -> 1.8 | D19: [€/l] | E19: --> | F19: =Dati!G13 -> 0.18176127 | G19: [€/kWh] | I19: Scenario 1: Utente con Ricarica Casa dalla RETE | O19: 0.31 | P19: [€/kWh]
B20: Elettrico rete | C20: =Dati!B14 -> 0.31 | D20: [€/kWh] | E20: --> | F20: =Dati!G14 -> 0.31 | G20: [€/kWh] | I20: Scenario 2: Utente con Ricarica Casa FOTOVOLTAICO (Autoprodotta) | O20: 0.24 | P20: [€/kWh]
B21: Elettrico autoprodotto | C21: =Dati!B15 -> 0.24 | D21: [€/kWh] | E21: --> | F21: =Dati!G15 -> 0.24 | G21: [€/kWh] | I21: Scenario 3: Utente SENZA Ricarica Casa (solo pubblico) | O21: 0.56 | P21: [€/kWh]
B22: Idrogeno grigio | C22: =Dati!B16 -> 2 | D22: [€/kg] | E22: --> | F22: =Dati!G16 -> 0.060006001 | G22: [€/kWh]
B23: Idrogeno elettrolisi rete | C23: =Dati!B17 -> 20 | D23: [€/kg] | E23: --> | F23: =Dati!G17 -> 0.60006001 | G23: [€/kWh]
B24: Idrogeno Verde elettrolisi PV | C24: =Dati!B18 -> 15 | D24: [€/kg] | E24: --> | F24: =Dati!G18 -> 0.450045 | G24: [€/kWh]
B28: Diesel | M28: Parametro | N28: Ƞ_WtT | O28: Ƞ_TtW | P28: Ƞ_WtW
B29: Modello | C29: Serbatoio | D29: Autonomia | E29: Consumo | G29: Costo | H29: Note | M29: Diesel | N29: =Dati!Z12 -> 0.87 | O29: =Dati!AB24 -> 0.3 | P29: =O29*N29 -> 0.261
C30: [l] | D30: [km] | E30: [l/km] | F30: [kWh/km] | G30: [€] | M30: Elettrico Rete | N30: =Dati!Z13 -> 0.5 | O30: =Dati!AB25 -> 0.8 | P30: =N30*O30 -> 0.4
B31: Yutong ZK6122 (Cina) | C31: 350 | D31: =C31/E31 -> 921.05263 | E31: 0.38 | F31: =E31*Dati!$G$4 -> 3.763178 | G31: 150000 | H31: Esportato in tutto il mondo | M31: Elettrico FV | N31: =Dati!Z14 -> 0.9 | O31: =Dati!AB25 -> 0.8 | P31: =N31*O31 -> 0.72
B32: Mercedes Citaro | C32: 325 | D32: =C32/E32 -> 812.5 | E32: 0.4 | F32: =E32*Dati!$G$4 -> 3.96124 | G32: 250000 | M32: Idrogeno Grigio (SMR) | N32: =Dati!Z15 -> 0.7 | O32: =Dati!$AB$26 -> 0.5 | P32: =N32*O32 -> 0.35
B33: Volvo 7900 | C33: 210 | D33: =C33/E33 -> 552.63158 | E33: 0.38 | F33: =E33*Dati!$G$4 -> 3.763178 | G33: 240000 | M33: Idrogeno da Rete (Elettrolisi) | N33: =Dati!Z16 -> 0.275 | O33: =Dati!$AB$26 -> 0.5 | P33: =N33*O33 -> 0.1375
B34: Media | C34: =AVERAGE(C31:C33) -> 295 | D34: =AVERAGE(D31:D33) -> 762.0614 | E34: =AVERAGE(E31:E33) -> 0.38666667 | F34: =AVERAGE(F31:F33) -> 3.8291987 | G34: =AVERAGE(G31:G33) -> 213333.33 | M34: Idrogeno da FV (Elettrolisi) | N34: =Dati!Z17 -> 0.62 | O34: =Dati!$AB$26 -> 0.5 | P34: =N34*O34 -> 0.31
M36: Emissioni CO2 WtT
B37: Elettrico (BEV) | M37: Diesel | N37: =Dati!R29 -> 0.039987479 | O37: [kg CO2/kWh] | Q37: 0.15 | R37: [kg CO₂/kWh] | S37: rispetto a TTW
B38: Modello | C38: Serbatoio | D38: Autonomia | E38: Consumo | G38: Costo | H38: Note | M38: Elettricità Mix ITA | N38: =Dati!R30 -> 0.215 | O38: [kg CO₂/kWh]
C39: [kWh] | D39: [km] | E39: [kWh/km] | F39: [kWh/km] | G39: [€] | M39: Elettricità da FV | N39: =Dati!R31 -> 0.055 | O39: [kg CO₂/kWh]
B40: BYD K9UB (Cina) | C40: 348 | D40: =C40/E40 -> 250.35971 | E40: 1.39 | F40: =E40 -> 1.39 | G40: 320000 | H40: Leader globale e-bus | M40: Idrogeno SMR | N40: =Dati!R32 -> 0.330033 | O40: [kg CO₂/kWh]
B41: Irizie ie bus | C41: 350 | D41: =C41/E41 -> 230.26316 | E41: 1.52 | F41: =E41 -> 1.52 | G41: 400000 | M41: Idrogeno (da elettrolisi con Rete IT) | N41: =Dati!R33 -> 0.3870387 | O41: [kg CO₂/kWh]
B42: Volvo 7900 Electric | C42: 300 | D42: =C42/E42 -> 200 | E42: 1.5 | F42: =E42 -> 1.5 | G42: 420000 | M42: Idrogeno (da elettrolisi con PV) | N42: =Dati!R34 -> 0.090009001 | O42: [kg CO₂/kWh] | Q42: oppure | R42: 3 | S42: [kgCO2/kgH2]
B43: Mercedes eCitaro | C43: 392 | D43: =C43/E43 -> 170.43478 | E43: 2.3 | F43: =E43 -> 2.3 | G43: 450000
B44: Media | C44: =AVERAGE(C40:C43) -> 347.5 | D44: =AVERAGE(D40:D43) -> 212.76441 | E44: =AVERAGE(E40:E43) -> 1.6775 | F44: =AVERAGE(F40:F43) -> 1.6775 | G44: =AVERAGE(G40:G43) -> 397500 | M44: Emissioni CO2 TtW
M45: Diesel | N45: =Dati!R40 -> 0.26658319 | O45: [kg CO2/kWh]
M46: Elettricità Mix ITA | N46: 0 | O46: [kg CO₂/kWh] | T46: LIFETIME
B47: Idrogeno (FCEV) | M47: Elettricità da FV | N47: 0 | O47: [kg CO₂/kWh] | T47: Categoria Veicolo | U47: Alimentazione | V47: Vita Utile [km] | W47: Vita Utile [anni] | X47: Percorso Medio
B48: Modello | C48: Serbatoio | D48: Autonomia | E48: Consumo | G48: Costo | H48: Pressione | M48: Idrogeno (da elettrolisi con PV) | N48: 0 | O48: [kg CO₂/kWh] | T48: Autobus Urbano | U48: Diesel | V48: =(800000 + 1200000)/2 -> 1000000 | W48: =27/2 -> 13.5 | X48: =(60000 +80000)/2 -> 70000
...

Sheet AUTOBUS ExtraUrbano
C2: DATI "TARGA" | G2: ENERGIA CONTENUTA | L2: ENERGIA & EMISSIONI ANNO TIPO | U2: COSTI
C3: Serbatoio | D3: Autonomia | E3: Consumo | G3: Well | H3: Tank | I3: Wheel | J3: η_WtW | L3: Carburante | M3: Energia Utile | N3: Energia primaria richiesta | O3: Emissioni CO2 - 170.000 km | Q3: Emissioni totale carburante | R3: Emissioni costruzione | S3: Emissioni Totali | U3: OPEx fuel | W3: OPEx Maintenance | Y3: CAPEx | AA3: Costo totale
C4: [l/kWh/kg] | D4: [km] | E4: [kWh/km] | G4: [kWh] | H4: [kWh] | I4: [kWh] | J4: [ - ] | L4: [l/kWh/kg] | M4: [kWh] | N4: [kWh] | O4: WtT - [kgCO2/anno] | P4: TtW [kgCO2/anno] | Q4: [tCO2/anno] | R4: [kg/CO2] | S4: [t CO2] | U4: [€/km] | V4: [€/anno] | W4: [€/km] | X4: [€/anno] | Y4: [€/anno] | Z4: [€] | AA4: [€/anno] | AB4: [€]
B5: Diesel | C5: =C34 -> 475 | D5: =D34 -> 1685.6313 | E5: =F34 -> 2.8058783 | G5: =H5/N29 -> 5406.8649 | H5: =C5*Dati!G4 -> 4703.9725 | I5: =H5*O29 -> 1716.95 | J5: =I5/G5 -> 0.31755 | L5: =C16*E34 -> 21250 | M5: =$C$16*E5 -> 210440.87 | N5: =M5/N29 -> 241886.06 | O5: =N37*M5 -> 8415 | P5: =N45*N5 -> 64482.759 | Q5: =(O5+P5)/1000 -> 72.897759 | R5: =N53 -> 50000 | S5: =(R5+(P5+O5)*$C$15)/1000 -> 1143.4664 | U5: =F19*$E$5 -> 0.51 | V5: =U5*$C$16 -> 38250 | W5: =Dati!D79 -> 0.23 | X5: =W5*$C$16 -> 17250 | Y5: =Z5/$C$15 -> 15166.667 | Z5: =G34 -> 227500 | AA5: =AB5/$C$15 -> 70666.667 | AB5: =((X5+V5)*$C$15+Z5) -> 1060000
B6: Elettrico rete | C6: =C43 -> 331.66667 | D6: =$D$43 -> 285.08454 | E6: =F43 -> 1.1666667 | G6: =H6/N30 -> 663.33333 | H6: =C6 -> 331.66667 | I6: =H6*O30 -> 271.96667 | J6: =I6/G6 -> 0.41 | L6: =M6 -> 87500 | M6: =$C$16*E6 -> 87500 | N6: =M6/N30 -> 175000 | O6: =N38*M6 -> 18812.5 | P6: 0 | Q6: =(O6+P6)/1000 -> 18.8125 | R6: =$N$54 -> 85000 | S6: =(R6+(P6+O6)*$C$15)/1000 -> 367.1875 | U6: =F20*$E$5 -> 0.86982228 | V6: =U6*$C$16 -> 65236.671 | W6: =Dati!$D$80 -> 0.135 | X6: =W6*$C$16 -> 10125 | Y6: =Z6/$C$15 -> 30000 | Z6: =$G$43 -> 450000 | AA6: =AB6/$C$15 -> 105361.67 | AB6: =((X6+V6)*$C$15+Z6) -> 1580425.1
B7: Elettrico autoprodotto | C7: =$C$43 -> 331.66667 | D7: =$D$43 -> 285.08454 | E7: =F43 -> 1.1666667 | G7: =H7/N31 -> 368.51852 | H7: =C7 -> 331.66667 | I7: =H7*O31 -> 271.96667 | J7: =I7/G7 -> 0.738 | L7: =$C$16*$F$43 -> 87500 | M7: =$C$16*E7 -> 87500 | N7: =M7/N31 -> 97222.222 | O7: =N39*M7 -> 4812.5 | P7: 0 | Q7: =(O7+P7)/1000 -> 4.8125 | R7: =$N$54 -> 85000 | S7: =(R7+(P7+O7)*$C$15)/1000 -> 157.1875 | U7: =F21*$E$5 -> 0.6734108 | V7: =U7*$C$16 -> 50505.81 | W7: =Dati!$D$80 -> 0.135 | X7: =W7*$C$16 -> 10125 | Y7: =Z7/$C$15 -> 30000 | Z7: =$G$43 -> 450000 | AA7: =AB7/$C$15 -> 90630.81 | AB7: =((X7+V7)*$C$15+Z7) -> 1359462.1
B8: Idrogeno Grigio | C8: =$C$53 -> 36.666667 | D8: =$D$53 -> 556.98006 | E8: =$F$53 -> 2.194225 | G8: =H8/N32 -> 1745.8571 | H8: =C8*Dati!$F$5 -> 1222.1 | I8: =H8*O32 -> 549.945 | J8: =I8/G8 -> 0.315 | L8: =$C$16*$E$53 -> 4937.5 | M8: =$C$16*E8 -> 164566.88 | N8: =M8/N32 -> 235095.54 | O8: =N40*M8 -> 54312.5 | P8: 0 | Q8: =(O8+P8)/1000 -> 54.3125 | R8: =$N$55 -> 95000 | S8: =(R8+(P8+O8)*$C$15)/1000 -> 909.6875 | U8: =F22*$E$5 -> 0.16836954 | V8: =U8*$C$16 -> 12627.715 | W8: =Dati!$D$81 -> 0.22 | X8: =W8*$C$16 -> 16500 | Y8: =Z8/$C$15 -> 45000 | Z8: =$G$53 -> 675000 | AA8: =AB8/$C$15 -> 74127.715 | AB8: =((X8+V8)*$C$15+Z8) -> 1111915.7
B9: Idrogeno rete | C9: =$C$53 -> 36.666667 | D9: =$D$53 -> 556.98006 | E9: =$F$53 -> 2.194225 | G9: =H9/N33 -> 4444 | H9: =C9*Dati!$F$5 -> 1222.1 | I9: =H9*O33 -> 549.945 | J9: =I9/G9 -> 0.12375 | L9: =$C$16*$E$53 -> 4937.5 | M9: =$C$16*E9 -> 164566.88 | N9: =M9/N33 -> 598425 | O9: =N41*M9 -> 63693.75 | P9: 0 | Q9: =(O9+P9)/1000 -> 63.69375 | R9: =$N$55 -> 95000 | S9: =(R9+(P9+O9)*$C$15)/1000 -> 1050.4062 | U9: =F23*$E$5 -> 1.6836954 | V9: =U9*$C$16 -> 126277.15 | W9: =Dati!$D$81 -> 0.22 | X9: =W9*$C$16 -> 16500 | Y9: =Z9/$C$15 -> 45000 | Z9: =$G$53 -> 675000 | AA9: =AB9/$C$15 -> 187777.15 | AB9: =((X9+V9)*$C$15+Z9) -> 2816657.3
B10: Idrogeno autoprodotto | C10: =$C$53 -> 36.666667 | D10: =$D$53 -> 556.98006 | E10: =$F$53 -> 2.194225 | G10: =H10/N34 -> 1971.129 | H10: =C10*Dati!$F$5 -> 1222.1 | I10: =H10*O34 -> 549.945 | J10: =I10/G10 -> 0.279 | L10: =$C$16*$E$53 -> 4937.5 | M10: =$C$16*E10 -> 164566.88 | N10: =M10/N34 -> 265430.44 | O10: =N42*M10 -> 14812.5 | P10: 0 | Q10: =(O10+P10)/1000 -> 14.8125 | R10: =$N$55 -> 95000 | S10: =(R10+(P10+O10)*$C$15)/1000 -> 317.1875 | U10: =F24*$E$5 -> 1.2627715 | V10: =U10*$C$16 -> 94707.865 | W10: =Dati!$D$81 -> 0.22 | X10: =W10*$C$16 -> 16500 | Y10: =Z10/$C$15 -> 45000 | Z10: =$G$53 -> 675000 | AA10: =AB10/$C$15 -> 156207.86 | AB10: =((X10+V10)*$C$15+Z10) -> 2343118
B13: Assunzioni: | H13: IPOTESI:
B14: Utilizzo | C14: =C15*C16 -> 1125000 | D14: km | H14: Parametri uniformi (C14, C15, C16) per mezzo a prescindere dal vettore energetico per rendere paragonabile il confronto
B15: Lifetime | C15: =D15 -> 15 | D15: 15 | F15: [y]
B16: Percorso | C16: =D16*100 -> 75000 | D16: 750 | F16: [km/y]
B18: COSTI FUEL
B19: Diesel | C19: =Dati!B13 -> 1.8 | D19: [€/l] | E19: --> | F19: =Dati!G13 -> 0.18176127 | G19: [€/kWh] | I19: Scenario 1: Utente con Ricarica Casa dalla RETE | O19: 0.31 | P19: [€/kWh]
B20: Elettrico rete | C20: =Dati!B14 -> 0.31 | D20: [€/kWh] | E20: --> | F20: =Dati!G14 -> 0.31 | G20: [€/kWh] | I20: Scenario 2: Utente con Ricarica Casa FOTOVOLTAICO (Autoprodotta) | O20: 0.24 | P20: [€/kWh]
B21: Elettrico autoprodotto | C21: =Dati!B15 -> 0.24 | D21: [€/kWh] | E21: --> | F21: =Dati!G15 -> 0.24 | G21: [€/kWh] | I21: Scenario 3: Utente SENZA Ricarica Casa (solo pubblico) | O21: 0.56 | P21: [€/kWh]
B22: Idrogeno grigio | C22: =Dati!B16 -> 2 | D22: [€/kg] | E22: --> | F22: =Dati!G16 -> 0.060006001 | G22: [€/kWh]
B23: Idrogeno elettrolisi rete | C23: =Dati!B17 -> 20 | D23: [€/kg] | E23: --> | F23: =Dati!G17 -> 0.60006001 | G23: [€/kWh]
B24: Idrogeno Verde elettrolisi PV | C24: =Dati!B18 -> 15 | D24: [€/kg] | E24: --> | F24: =Dati!G18 -> 0.450045 | G24: [€/kWh]
B28: Diesel | M28: Parametro | N28: Ƞ_WtT | O28: Ƞ_TtW | P28: Ƞ_WtW
B29: Modello | C29: Serbatoio | D29: Autonomia | E29: Consumo | G29: Costo | H29: Note | M29: Diesel | N29: =Dati!Z12 -> 0.87 | O29: =Dati!AC24 -> 0.365 | P29: =O29*N29 -> 0.31755
C30: [l] | D30: [km] | E30: [l/km] | F30: [kWh/km] | G30: [€] | M30: Elettrico Rete | N30: =Dati!Z13 -> 0.5 | O30: =Dati!$AC$25 -> 0.82 | P30: =O30*N30 -> 0.41
B31: Iveco Crossway Diesel 12 m | C31: 500 | D31: =C31/E31 -> 1754.386 | E31: 0.285 | F31: =E31*Dati!$G$4 -> 2.8223835 | G31: =(275+200)/2*1000 -> 237500 | H31: Motore Cursor 9, bus extraurbano, Euro VI ​ | M31: Elettrico FV | N31: =Dati!Z14 -> 0.9 | O31: =Dati!$AC$25 -> 0.82 | P31: =O31*N31 -> 0.738
B32: ICBus RE Series Diesel | C32: 600 | D32: =C32/E32 -> 2181.8182 | E32: =0.55/2 -> 0.275 | F32: =E32*Dati!$G$4 -> 2.7233525 | G32: =(210+250)/2*1000 -> 230000 | H32: Cummins L9, commercial bus U.S. | M32: Idrogeno Grigio (SMR) | N32: =Dati!Z15 -> 0.7 | O32: =Dati!$AC$26 -> 0.45 | P32: =O32*N32 -> 0.315
B33: Mercedes-Benz O530 Diesel | C33: =(250+400)/2 -> 325 | D33: =C33/E33 -> 1120.6897 | E33: 0.29 | F33: =E33*Dati!$G$4 -> 2.871899 | G33: 215000 | H33: Bus urbano/extraurbano, Euro VI | M33: Idrogeno da Rete (Elettrolisi) | N33: =Dati!Z16 -> 0.275 | O33: =Dati!$AC$26 -> 0.45 | P33: =O33*N33 -> 0.12375
B34: Media | C34: =AVERAGE(C31:C33) -> 475 | D34: =AVERAGE(D31:D33) -> 1685.6313 | E34: =AVERAGE(E31:E33) -> 0.28333333 | F34: =AVERAGE(F31:F33) -> 2.8058783 | G34: =AVERAGE(G31:G33) -> 227500 | M34: Idrogeno da FV (Elettrolisi) | N34: =Dati!Z17 -> 0.62 | O34: =Dati!$AC$26 -> 0.45 | P34: =O34*N34 -> 0.279
M36: Emissioni CO2 WtT
B37: Elettrico (BEV) | M37: Diesel | N37: =Dati!R29 -> 0.039987479 | O37: [kg CO2/kWh] | Q37: 0.15 | R37: [kg CO₂/kWh] | S37: rispetto a TTW
B38: Modello | C38: Serbatoio | D38: Autonomia | E38: Consumo | G38: Costo | H38: Note | M38: Elettricità Mix ITA | N38: =Dati!R30 -> 0.215 | O38: [kg CO₂/kWh]
C39: [kWh] | D39: [km] | E39: [kWh/km] | F39: [kWh/km] | G39: [€] | M39: Elettricità da FV | N39: =Dati!R31 -> 0.055 | O39: [kg CO₂/kWh]
B40: Yutong T12E | C40: 440 | D40: =C40/E40 -> 382.6087 | E40: =2.3/2 -> 1.15 | F40: =E40 -> 1.15 | G40: 500000 | H40: Full electric coach extraurbano, autonomia 500+ km | M40: Idrogeno SMR | N40: =Dati!R32 -> 0.330033 | O40: [kg CO₂/kWh]
B41: Volvo 7900 Electric | C41: =550/2 -> 275 | D41: =C41/E41 -> 229.16667 | E41: =2.4/2 -> 1.2 | F41: =E41 -> 1.2 | G41: 450000 | H41: Bus elettrico extraurbano | M41: Idrogeno (da elettrolisi con Rete IT) | N41: =Dati!R33 -> 0.3870387 | O41: [kg CO₂/kWh]
B42: Solaris Urbino Electric 12 m | C42: =(210+350)/2 -> 280 | D42: =C42/E42 -> 243.47826 | E42: =2.3/2 -> 1.15 | F42: =E42 -> 1.15 | G42: 400000 | H42: Bus elettrico per trasporto extraurbano e urbano | M42: Idrogeno (da elettrolisi con PV) | N42: =Dati!R34 -> 0.090009001 | O42: [kg CO₂/kWh] | Q42: oppure | R42: 3 | S42: [kgCO2/kgH2]
B43: Media | C43: =AVERAGE(C40:C42) -> 331.66667 | D43: =AVERAGE(D40:D42) -> 285.08454 | E43: =AVERAGE(E40:E42) -> 1.1666667 | F43: =AVERAGE(F40:F42) -> 1.1666667 | G43: =AVERAGE(G40:G42) -> 450000
M44: Emissioni CO2 TtW
M45: Diesel | N45: =Dati!R40 -> 0.26658319 | O45: [kg CO2/kWh]
M46: Elettricità Mix ITA | N46: 0 | O46: [kg CO₂/kWh] | T46: LIFETIME
B47: Idrogeno (FCEV) | M47: Elettricità da FV | N47: 0 | O47: [kg CO₂/kWh] | T47: Categoria Veicolo | U47: Alimentazione | V47: Vita Utile [km] | W47: Vita Utile [anni] | X47: Percorso Medio
B48: Modello | C48: Serbatoio | D48: Autonomia | E48: Consumo | G48: Costo | H48: Pressione | M48: Idrogeno (da elettrolisi con PV) | N48: 0 | O48: [kg CO₂/kWh] | T48: Autobus Extraurbano | U48: Diesel | V48: =(1000000+1500000)/2 -> 1250000 | W48: 15 | X48: =170/2*1000 -> 85000
...

Sheet CALORE
B2: Sistema di Riscaldamento | C2: Taglia | D2: η, COP | E2: Vettore | F2: Consumo Vettore | H2: Energia Primaria | I2: η_processo | J2: Emissioni WTT | K2: Emissioni TTW | L2: Emissioni WTW | M2: Emissioni costruzione | N2: Emissioni totali annue | O2: Emissioni totali LCA | Q2: OPEx fuel | R2: OPEx Maintenance | S2: CAPEx | U2: Costo totale
C3: [kW] | D3: [ - ] | E3: [tipo] | F3: [kWh/y] | H3: [kWh] | I3: [ - ] | J3: [kgCO2/anno] | K3: [kgCO2/anno] | L3: [kgCO2/anno] | M3: [kg_CO2] | N3: [t_CO2/y] | O3: [t CO2] | Q3: [€/anno] | R3: [€/anno] | S3: [€/anno] | T3: [€] | U3: [€/anno] | V3: [€]
B4: Caldaia a Gasolio | C4: =D46 -> 23 | D4: 0.9 | E4: Gasolio | F4: =$J$18/D4 -> 11111.111 | H4: =F4/C35 -> 12771.392 | I4: =E35 -> 0.783 | J4: =F4*G35 -> 444.30532 | K4: =F4*H35 -> 2962.0355 | L4: =J4+K4 -> 3406.3408 | M4: =C46 -> 1200 | N4: =(L4+M4/$J$19)/1000 -> 3.4663408 | O4: =N4*$J$19 -> 69.326816 | Q4: =F4*F18 -> 2019.5696 | R4: =F46 -> 225 | S4: =T4/$J$19 -> 175 | T4: =E46 -> 3500 | U4: =S4+R4+Q4 -> 2419.5696 | V4: =U4*$J$19 -> 48391.393
B5: Caldaia a Metano | C5: =D47 -> 27 | D5: 1 | E5: CH4 | F5: =$J$18/D5 -> 10000 | H5: =F5/C36 -> 10989.011 | I5: =E36 -> 0.91 | J5: =F5*G36 -> 575 | K5: =F5*H36 -> 2050 | L5: =J5+K5 -> 2625 | M5: =C47 -> 950 | N5: =(L5+M5/$J$19)/1000 -> 2.6725 | O5: =N5*$J$19 -> 53.45 | Q5: =F5*F25 -> 990.61522 | R5: =F47 -> 200 | S5: =T5/$J$19 -> 137.5 | T5: =E47 -> 2750 | U5: =S5+R5+Q5 -> 1328.1152 | V5: =U5*$J$19 -> 26562.304
B6: Stufa a Pellet | C6: =D48 -> 10 | D6: =D37 -> 0.9 | E6: Pellet | F6: =$J$18/D6 -> 11111.111 | H6: =F6/C37 -> 13071.895 | I6: =E37 -> 0.765 | J6: =F6*G37 -> 422.22222 | K6: 0 | L6: =J6+K6 -> 422.22222 | M6: =C48 -> 650 | N6: =(L6+M6/$J$19)/1000 -> 0.45472222 | O6: =N6*$J$19 -> 9.0944444 | Q6: =F6*F24 -> 680.27211 | R6: =F48 -> 300 | S6: =T6/$J$19 -> 150 | T6: =E48 -> 3000 | U6: =S6+R6+Q6 -> 1130.2721 | V6: =U6*$J$19 -> 22605.442
B7: Riscaldamento Elettrico rete (Effetto Joule) | C7: =D49 -> 7.5 | D7: 1 | E7: Elc rete | F7: =$J$18/D7 -> 10000 | H7: =F7/C38 -> 20000 | I7: =E38 -> 0.5 | J7: =F7*G38 -> 2150 | K7: 0 | L7: =J7+K7 -> 2150 | M7: =C49 -> 225 | N7: =(L7+M7/$J$19)/1000 -> 2.16125 | O7: =N7*$J$19 -> 43.225 | Q7: =F7*F19 -> 3100 | R7: =F49 -> 30 | S7: =T7/$J$19 -> 50 | T7: =E49 -> 1000 | U7: =S7+R7+Q7 -> 3180 | V7: =U7*$J$19 -> 63600
B8: Riscaldamento Elettrico auto (Effetto Joule) | C8: =D49 -> 7.5 | D8: 1 | E8: Elc autoprodotta | F8: =$J$18/D8 -> 10000 | H8: =F8/C39 -> 11111.111 | I8: =E39 -> 0.9 | J8: =F8*G39 -> 550 | K8: 0 | L8: =J8+K8 -> 550 | M8: =C49 -> 225 | N8: =(L8+M8/$J$19)/1000 -> 0.56125 | O8: =N8*$J$19 -> 11.225 | Q8: =F8*F20 -> 2400 | R8: =F49 -> 30 | S8: =T8/$J$19 -> 50 | T8: =E49 -> 1000 | U8: =S8+R8+Q8 -> 2480 | V8: =U8*$J$19 -> 49600
B9: PdC rete | C9: =D50 -> 3 | D9: =C28 -> 3 | E9: Elc da rete | F9: =$J$18/D9 -> 3333.3333 | H9: =F9/C38 -> 6666.6667 | I9: =E38 -> 0.5 | J9: =F9*G38 -> 716.66667 | K9: 0 | L9: =J9+K9 -> 716.66667 | M9: =C50 -> 1400 | N9: =(L9+M9/$J$19)/1000 -> 0.78666667 | O9: =N9*$J$19 -> 15.733333 | Q9: =F9*F19 -> 1033.3333 | R9: =F50 -> 150 | S9: =T9/$J$19 -> 575 | T9: =E50 -> 11500 | U9: =S9+R9+Q9 -> 1758.3333 | V9: =U9*$J$19 -> 35166.667
B10: PdC autoprodotta | C10: =D50 -> 3 | D10: =C28 -> 3 | E10: Elc autoprodotta | F10: =$J$18/D10 -> 3333.3333 | H10: =F10/C39 -> 3703.7037 | I10: =E39 -> 0.9 | J10: =F10*G39 -> 183.33333 | K10: 0 | L10: =J10+K10 -> 183.33333 | M10: =C50 -> 1400 | N10: =(L10+M10/$J$19)/1000 -> 0.25333333 | O10: =N10*$J$19 -> 5.0666667 | Q10: =F10*F20 -> 800 | R10: =F50 -> 150 | S10: =T10/$J$19 -> 575 | T10: =E50 -> 11500 | U10: =S10+R10+Q10 -> 1525 | V10: =U10*$J$19 -> 30500
B11: PdC Geotermica rete | C11: =D51 -> 2 | D11: =C29 -> 4.5 | E11: Elc da rete | F11: =$J$18/D11 -> 2222.2222 | H11: =F11/C38 -> 4444.4444 | I11: =E38 -> 0.5 | J11: =F11*G38 -> 477.77778 | K11: 0 | L11: =J11+K11 -> 477.77778 | M11: =C51 -> 2000 | N11: =(L11+M11/$J$19)/1000 -> 0.57777778 | O11: =N11*$J$19 -> 11.555556 | Q11: =F11*F19 -> 688.88889 | R11: =F51 -> 150 | S11: =T11/$J$19 -> 1200 | T11: =E51 -> 24000 | U11: =S11+R11+Q11 -> 2038.8889 | V11: =U11*$J$19 -> 40777.778
B12: PdC Geotermica autoprodotta | C12: =D51 -> 2 | D12: =C29 -> 4.5 | E12: Elc autoprodotta | F12: =$J$18/D12 -> 2222.2222 | H12: =F12/C39 -> 2469.1358 | I12: =E39 -> 0.9 | J12: =F12*G39 -> 122.22222 | K12: 0 | L12: =J12+K12 -> 122.22222 | M12: =C51 -> 2000 | N12: =(L12+M12/$J$19)/1000 -> 0.22222222 | O12: =N12*$J$19 -> 4.4444444 | Q12: =F12*F20 -> 533.33333 | R12: =F51 -> 150 | S12: =T12/$J$19 -> 1200 | T12: =E51 -> 24000 | U12: =S12+R12+Q12 -> 1883.3333 | V12: =U12*$J$19 -> 37666.667
B13: Caldaia a idrogeno girgio | C13: =D52 -> 27 | D13: 0.9 | E13: H2 grigio | F13: =$J$18/D13 -> 11111.111 | H13: =F13/C40 -> 15873.016 | I13: =E40 -> 0.63 | J13: =F13*G40 -> 3667.0334 | K13: 0 | L13: =J13+K13 -> 3667.0334 | M13: =C52 -> 1200 | N13: =(L13+M13/$J$19)/1000 -> 3.7270334 | O13: =N13*$J$19 -> 74.540667 | Q13: =F13*F21 -> 666.73334 | R13: =F52 -> 509.09091 | S13: =T13/$J$19 -> 350 | T13: =E52 -> 7000 | U13: =S13+R13+Q13 -> 1525.8242 | V13: =U13*$J$19 -> 30516.485
B14: Caldaia a idrogeno verde rete | C14: =D52 -> 27 | D14: 0.9 | E14: H2 elettrolisi rete | F14: =$J$18/D14 -> 11111.111 | H14: =F14/C41 -> 40404.04 | I14: =E41 -> 0.2475 | J14: =F14*G41 -> 4300.43 | K14: 0 | L14: =J14+K14 -> 4300.43 | M14: =C52 -> 1200 | N14: =(L14+M14/$J$19)/1000 -> 4.36043 | O14: =N14*$J$19 -> 87.208601 | Q14: =F14*F22 -> 6667.3334 | R14: =F52 -> 509.09091 | S14: =T14/$J$19 -> 350 | T14: =E52 -> 7000 | U14: =S14+R14+Q14 -> 7526.4243 | V14: =U14*$J$19 -> 150528.49
B15: Caldaia a idrogeno verde auto | C15: =D52 -> 27 | D15: 0.9 | E15: H2 verde | F15: =$J$18/D15 -> 11111.111 | H15: =F15/C42 -> 17921.147 | I15: =E42 -> 0.558 | J15: =F15*G42 -> 1000.1 | K15: 0 | L15: =J15+K15 -> 1000.1 | M15: =C52 -> 1200 | N15: =(L15+M15/$J$19)/1000 -> 1.0601 | O15: =N15*$J$19 -> 21.202 | Q15: =F15*F23 -> 5000.5001 | R15: =F52 -> 509.09091 | S15: =T15/$J$19 -> 350 | T15: =E52 -> 7000 | U15: =S15+R15+Q15 -> 5859.591 | V15: =U15*$J$19 -> 117191.82
B17: COSTI FUEL | I17: IPOTESI
B18: Diesel | C18: =Dati!B13 -> 1.8 | D18: [€/l] | E18: --> | F18: =Dati!G13 -> 0.18176127 | G18: [€/kWh] | I18: Fabbisogno Riscaldamento annuo | J18: =K18*1000 -> 10000 | K18: 10 | M18: [kWh_th]
B19: Elettrico da Rete | C19: =Dati!B14 -> 0.31 | D19: [€/kWh] | E19: --> | F19: =Dati!G14 -> 0.31 | G19: [€/kWh] | I19: Lifetime | J19: 20 | K19: 1 | M19: [y]
B20: Elettrico Autoprodotto (PV) | C20: =Dati!B15 -> 0.24 | D20: [€/kWh] | E20: --> | F20: =Dati!G15 -> 0.24 | G20: [€/kWh]
B21: Idrogeno Grigio | C21: =Dati!B16 -> 2 | D21: [€/kg] | E21: --> | F21: =Dati!G16 -> 0.060006001 | G21: [€/kWh]
B22: Idrogeno da Rete | C22: =Dati!B17 -> 20 | D22: [€/kg] | E22: --> | F22: =Dati!G17 -> 0.60006001 | G22: [€/kWh]
B23: Idrogeno Verde Autoprodotto | C23: =Dati!B18 -> 15 | D23: [€/kg] | E23: --> | F23: =Dati!G18 -> 0.450045 | G23: [€/kWh]
B24: Pellet | C24: =Dati!B19 -> 4.5 | D24: [€/sacco] | E24: --> | F24: =Dati!G19 -> 0.06122449 | G24: [€/kWh]
B25: Metano | C25: =Dati!B20 -> 0.95 | D25: [€/Sm3] | E25: --> | F25: =Dati!G20 -> 0.099061522 | G25: [€/kWh]
B27: COP PdC
B28: PdC Aria-H2O | C28: =D28/10 -> 3 | D28: 30
B29: PdC Geotermica | C29: =D29/10 -> 4.5 | D29: 45
C33: Rendimento | G33: Emissioni [kgCO2eq/kWh]
B34: Vettore Energetico | C34: WTT | D34: TTW | E34: WTW | G34: WTT | H34: TTW
B35: Gasolio | C35: =Dati!Z12 -> 0.87 | D35: =Dati!Z27 -> 0.9 | E35: =C35*D35 -> 0.783 | G35: =Dati!R29 -> 0.039987479 | H35: =Dati!R40 -> 0.26658319
B36: Gas Metano | C36: =Dati!Z18 -> 0.91 | D36: =Dati!Z29 -> 1 | E36: =C36*D36 -> 0.91 | G36: =Dati!R35 -> 0.0575 | H36: =Dati!R42 -> 0.205
B37: Pellet | C37: =Dati!Z19 -> 0.85 | D37: =Dati!Z28 -> 0.9 | E37: =C37*D37 -> 0.765 | G37: =Dati!R36 -> 0.038 | H37: 0
B38: Elettricità da rete | C38: =Dati!Z13 -> 0.5 | D38: 1 | E38: =C38*D38 -> 0.5 | G38: =Dati!R30 -> 0.215 | H38: 0
B39: Elettricità autoprodotta | C39: =Dati!Z14 -> 0.9 | D39: 1 | E39: =C39*D39 -> 0.9 | G39: =Dati!R31 -> 0.055 | H39: 0
B40: Idrogeno (da Metano - SMR) | C40: =Dati!Z15 -> 0.7 | D40: 0.9 | E40: =C40*D40 -> 0.63 | G40: =Dati!R32 -> 0.330033 | H40: 0
B41: Idrogeno Elettrolisi rete | C41: =Dati!Z16 -> 0.275 | D41: 0.9 | E41: =C41*D41 -> 0.2475 | G41: =Dati!R33 -> 0.3870387 | H41: 0
B42: Idrogeno (da Elettrolisi) | C42: =Dati!Z17 -> 0.62 | D42: 0.9 | E42: =C42*D42 -> 0.558 | G42: =Dati!R34 -> 0.090009001 | H42: 0
B44: CALDAIE | C44: Stima Emissioni di Produzione (kg CO₂eq) | D44: Taglia | E44: CAPEx | F44: OPEx
B45: Tecnologia di Riscaldamento | C45: [kgCO2_eq] | D45: [kW] | E45: [€] | F45: [€/anno]
B46: Caldaia a Gasolio | C46: =CALORE!D59 -> 1200 | D46: 23 | E46: 3500 | F46: 225
B47: Caldaia a Metano a Condensazione | C47: =CALORE!D58 -> 950 | D47: =54/2 -> 27 | E47: =5500/2 -> 2750 | F47: 200
...

Sheet Produzione H2
B2: Fabbisogno di idrogeno | C2: 5 | H2: tonnes
B5: CF electrolyzer | C5: =D5/100 -> 0.45 | D5: 45
B7: Fabbisogno elettrico annuo | C7: [kWh] | D7: =C2*55*1000 -> 275000
C8: [MWh] | D8: =D7/1000 -> 275
B10: Superficie necessaria | C10: [m2]
C11: [ha]
B14: IMPIANTO | F14: [W/m2] | G14: [h_eq] | H14: [kWh/m2]
B15: A terra | C15: Normale | D15: 600 | E15: [kW/ha] | F15: =D15/10 -> 60 | G15: 1200 | H15: =F15*G15/1000 -> 72
C16: Inseguimento | D16: 700 | E16: [kW/ha] | F16: =D16/10 -> 70 | G16: =G15*0.15+G15 -> 1380 | H16: =F16*G16/1000 -> 96.6
B17: Sul tetto | C17: a falda | D17: =C67/C66 -> 227.27273 | E17: [W/m2] | F17: =D17/10 -> 22.727273 | G17: 1200
C18: piano | D18: =D17*0.5 -> 113.63636 | E18: [W/m2] | F18: =D18/10 -> 11.363636 | G18: 1200
B29: Di quanto idrogeno ho bisogno per sostituire i consumi rispetto allo stesso veicolo elettrico per un anno tipo? | S29: HP | T29: si considera contemporaneità tra produzuio
B30: E quanto fotovoltaico mi serve per fare le stesse cose con una soluzione elettrica? E le emissioni?
D32: Carburante | E32: Consumo vettore | F32: Energia primaria [elettrica] | I32: Superficie necessaria
D33: [kWh-kg] | E33: [kWh] | F33: 0 | I33: [m2] | J33: Rapporto
B34: Automobile | C34: Elc | D34: =AUTO!L7 -> 2050 | E34: =AUTO!M7 -> 2050 | F34: =AUTO!N8 -> 2277.7778 | I34: =F34/$H$15 -> 31.635802 | J34: =I35/I34 -> 3.5401652
C35: H2 | D35: =AUTO!L9 -> 150 | E35: =AUTO!M9 -> 4999.5 | F35: =AUTO!N11 -> 8063.7097 | I35: =F35/$H$15 -> 111.99597
B36: Camion | C36: Elc | T36: San vito 2011 | V36: 204 | W36: GWh | Y36: energia elettrica totale
C37: H2 | V37: 60.88 | W37: km2 | Y37: =V36/Dati!Z17 -> 329.03226 | Z37: GWh
B38: Autobus Urbano | C38: Elc
C39: H2 | V39: =V36/H15 -> 2.8333333 | W39: km2
B40: Autobus Extraurbano | C40: Elc | V40: =Y37/H15 -> 4.5698925
C41: H2
B42: PdC | D42: =F42 -> 2469.1358 | E42: =CALORE!F12 -> 2222.2222 | F42: =CALORE!H12 -> 2469.1358 | J42: =F43/F42 -> 7.2580645
B43: Caldaia a H2 | D43: =F43/Dati!F6 -> 537.68818 | E43: =CALORE!F15 -> 11111.111 | F43: =CALORE!H15 -> 17921.147
H48: PRODUZIONE ANNUA
I49: [t_H2]
I50: =#REF!/(55+55*0.05)/1000 -> #REF! | J50: Sufficiente per: | L50: =$I$50/AUTO!L11*1000 -> #REF! | M50: macchine / anno | P50: che sarebbero | R50: =#REF!/AUTO!L7 -> #REF! | S50: fossero elettriche
I51: =#REF!/(55+55*0.05)/1000 -> #REF! | L51: =$I$50/CAMION!L10*1000 -> #REF! | M51: camion / anno | R51: =#REF!/CAMION!L7 -> #REF! | S51: fossero elettrici
L52: =$I$50/'AUTOBUS Urbano'!L10*1000 -> #REF! | M52: autobus urbani / anno | R52: =#REF!/'AUTOBUS Urbano'!L7 -> #REF! | S52: fossero elettrici
L53: =$I$50/'AUTOBUS ExtraUrbano'!L10*1000 -> #REF! | M53: autobus extraurbani / anno | R53: =#REF!/'AUTOBUS ExtraUrbano'!L7 -> #REF! | S53: fossero elettrici
B66: Dimensione pannello | C66: 2.2 | D66: [m2]
B67: Potenza | C67: 500 | D67: [W]
B69: Perdite | C69: 0.2

Sheet Dati
A1: COSTI fuel | B1: [€/l] | D1: [€/kg] | F1: Pci | H1: ρ | N1: IDROGENO | Y1: RENDIMENTI WtT
F2: [kWh/kg] | G2: [kWh/dm3] | H2: [kg/dm3] | N2: p | O2: [kPa] | P2: =P3*101325/1000 -> 31005.45 | Y2: Vettore Energetico | Z2: Processo Principale | AA2: Note Principali
A3: Benzina | B3: 1.7 | C3: 2 | D3: =C3/H3 -> 2.6666667 | F3: 11.67 | G3: =F3*H3 -> 8.7525 | H3: 0.75 | O3: [bar] | P3: 306 | Y3: Benzina | Z3: Greggio → Raffinazione → Trasporto → Distributore | AA3: La raffinazione è un processo energivoro.
A4: Gasolio | B4: 1.65 | C4: 1.95 | D4: =C4/H4 -> 2.3353293 | F4: 11.86 | G4: =F4*H4 -> 9.9031 | H4: 0.835 | N4: MM | O4: [g/mole] | P4: =1.008*2 -> 2.016 | Y4: Diesel | Z4: Greggio → Raffinazione → Trasporto → Distributore | AA4: Processo di raffinazione leggermente più efficiente della benzina.
A5: Idrogeno grigio | B5: 1 | C5: 2 | D5: 1 | E5: 2 | F5: 33.33 | G5: =F5*H5 -> 0.85479891 | H5: =P10/1000 -> 0.025646532 | O5: [kg/mole] | P5: =P4/1000 -> 0.002016 | Y5: Idrogeno (da Metano) | Z5: Steam Methane Reforming (SMR) → Compressione (700 bar) | AA5: La compressione ad alta pressione richiede molta energia.
A6: Idrogeno verde | B6: 12 | C6: 18 | D6: 12 | E6: 18 | F6: 33.33 | G6: =F6*H6 -> 2.36643 | H6: =P11/1000 -> 0.071 | N6: T | O6: [k] | P6: =P7+273.15 -> 293.15 | Y6: Idrogeno (Elettrolisi) | Z6: Elettricità → Elettrolisi → Compressione (700 bar) | AA6: L'elettrolisi e la compressione sono processi molto inefficienti.
A7: Pellet | D7: 2 | E7: 5 | F7: 4.9 | O7: [°C] | P7: 20 | Y7: Elettricità (Fotovoltaico) | Z7: Sole → Inverter → Rete/Caricabordo → Batteria Auto | AA7: Include perdite di inverter, trasmissione e ricarica della batteria.
A8: Metano | B8: 0.95 | C8: [€/sm3] | D8: =B8/H8 -> 1.3268156 | F8: =G8/H8 -> 13.393855 | G8: 9.59 | H8: 0.716 | N8: R | O8: [J/mol K] | P8: 8.314
G9: [kWh/sm3] | N9: v | O9: [m3/kg] | P9: =P8*P6/(P5*P2)/1000 -> 0.038991627 | Y9: Ƞ Well-to-Tank (WtT) - Conversione da energia primaria (Well) al Serbatoio (Tank) | AA9: Note
N10: ρ | O10: [kg/m3] | P10: =1/P9 -> 25.646532 | Y10: Vettore | Z10: Ƞ Well-to-Tank (WtT)
A11: COSTI FUEL | I11: Dati Originali (29/10/2025) | N11: ρliq | O11: [kg/m3] | P11: 71 | Y11: Benzina | Z11: 0.85 | AA11: Greggio → Raffinazione → Trasporto → Distributore
A12: Benzina | B12: =C12/1000 -> 1.9 | C12: 1900 | E12: [€/l] | F12: --> | G12: =B12/G3 -> 0.21708083 | H12: [€/kWh] | I12: 1.9 | J12: [€/l] | Y12: Diesel | Z12: 0.87 | AA12: Greggio → Raffinazione → Trasporto → Distributore
A13: Diesel | B13: =C13/1000 -> 1.8 | C13: 1800 | E13: [€/l] | F13: --> | G13: =B13/G4 -> 0.18176127 | H13: [€/kWh] | I13: 1.8 | J13: [€/l] | Y13: Elettrico Rete | Z13: 0.5 | AA13: Mix di Generazione Elettrica Nazionale → Trasmissione → Distribuzione
A14: Elettrico da Rete | B14: =C14/100 -> 0.31 | C14: 31 | E14: [€/kWh] | F14: --> | G14: =B14 -> 0.31 | H14: [€/kWh] | I14: 0.31 | J14: [€/kWh] | N14: METANO | Y14: Elettrico FV | Z14: 0.9 | AA14: PV → Inverter → Rete/Caricabordo → Batteria Auto
A15: Elettrico Autoprodotto (PV) | B15: =C15/100 -> 0.24 | C15: 24 | E15: [€/kWh] | F15: --> | G15: =B15 -> 0.24 | H15: [€/kWh] | I15: 0.24 | J15: [€/kWh] | N15: p | O15: [kPa] | P15: =P16*101325/1000 -> 101.325 | Y15: Idrogeno Grigio (SMR) | Z15: 0.7 | AA15: Steam Methane Reforming (SMR) → Compressione (700 bar)
A16: Idrogeno Grigio | B16: =C16/100 -> 2 | C16: 200 | E16: [€/kg] | F16: --> | G16: =B16/$F$5 -> 0.060006001 | H16: [€/kWh] | I16: 2 | J16: [€/kg] | O16: [bar] | P16: 1 | Y16: Idrogeno da Rete (Elettrolisi) | Z16: 0.275 | AA16: Elettricità → Elettrolisi → Compressione (700 bar)
A17: Idrogeno da Rete | B17: =C17/100 -> 20 | C17: 2000 | E17: [€/kg] | F17: --> | G17: =B17/$F$5 -> 0.60006001 | H17: [€/kWh] | I17: 20 | J17: [€/kg] | N17: MM | O17: [g/mole] | P17: =1.008*4+ 12.011 -> 16.043 | Y17: Idrogeno da FV (Elettrolisi) | Z17: 0.62 | AA17: Elettricità → Elettrolisi → Compressione (700 bar)
A18: Idrogeno Verde Autoprodotto | B18: =C18/100 -> 15 | C18: 1500 | E18: [€/kg] | F18: --> | G18: =B18/$F$5 -> 0.450045 | H18: [€/kWh] | I18: 15 | J18: [€/kg] | O18: [kg/mole] | P18: =P17/1000 -> 0.016043 | Y18: Metano | Z18: 0.91
A19: Pellet | B19: =C19/20 -> 4.5 | C19: 90 | D19: 90 | E19: [€/sacco] | F19: --> | G19: =B19/F7/15 -> 0.06122449 | H19: [€/kWh] | I19: 4.5 | J19: [€/sacco] | N19: T | O19: [k] | P19: =P20+273.15 -> 273.15 | Y19: Pellet | Z19: 0.85
A20: Metano | B20: =C20/100 -> 0.95 | C20: 95 | D20: 25 | E20: [€/Sm3] | F20: --> | G20: =B20/G8 -> 0.099061522 | H20: [€/kWh] | I20: 0.95 | J20: [€/Sm3] | O20: [°C] | P20: 0
N21: R | O21: [J/mol K] | P21: 8.314 | Y21: Ƞ Tank to Wheel - Conversione da Serbatoio (Tank) alla ruota (Wheel)
N22: v | O22: [m3/kg] | P22: =P21*P19/(P18*P15)/1000 -> 1.3970406 | Y22: Veicolo | Z22: Automobile | AA22: Camion (40 t) | AB22: Autobus Urbano | AC22: Autobus Extraurbano | AD22: Note
A23: ENERGIA ELETTRICA | B23: Potenza | D23: Tempo Ricarica | F23: Costo | N23: ρ | O23: [kg/m3] | P23: =1/P22 -> 0.71579881 | Y23: Benzina | Z23: 0.25 | AA23: - | AB23: - | AC23: -
A24: Tipologia di Ricarica | B24: [kW] | D24: [min] per 50 kWh | F24: [€/kWh] | R24: 0.038 | Y24: Diesel | Z24: 0.32 | AA24: 0.4 | AB24: 0.3 | AC24: =(35+38)/2/100 -> 0.365
A25: Lenta (AC) - Casa | B25: 3.5 | C25: 7.4 | D25: =7*60 -> 420 | E25: =10*60 -> 600 | F25: 0.2 | G25: 0.28 | Y25: Elettricità | Z25: 0.9 | AA25: 0.85 | AB25: 0.8 | AC25: 0.82
